Workbook
Name TAXRATE: _xludf.LAMBDA(g, i, h, j, k, l, m, IF(g="capital",0.1)+IF(h="port",0.1)+IF(i="citadel",0.05)+IF(j="walls",-0.07)+IF(k="plaza",0.05)+IF(l="temple",0.01)+IF(m="shanty town",0.05))

Sheet New Provinces Summary
B1: Gold Kastar Coins | C1: Total Population | D1: Urban Population | E1: Rural Population | F1: Gold Net Income | G1: Retinues | H1: Knights | I1: Raised Levys | J1: Possible Levys | K1: Urban Population % | L1: Rural Population % | M1: Future Gold
A2: The Crownlands | B2: 201311.58 | C2: ='Province Import (Ignore)'!I5 -> 6198707 | D2: =SUM(Cities!E2:E13) -> 211771 | E2: =C2-D2 -> 5986936 | F2: ='Provincial Economics'!D2-'Provincial Economics'!C2 -> -41088.726 | G2: ='New Retinues Summary'!S3 -> 400 | H2: ='Knights Breakdown'!B2 -> 1942.2476 | I2: =SUM('Duchies Secret Sheet'!$C$16:$C$20) -> 25946 | J2: =IFERROR(__xludf.DUMMYFUNCTION("TO_TEXT(round(RANDBETWEEN(1000,10000)+(C2*0.005)))&TO_TEXT(round(RANDBETWEEN(1000,10000)-(C2*0.005)))"),"38714-26229") -> 38714-26229 | K2: =D2/C2 -> 0.034163738 | L2: =E2/C2 -> 0.96583626 | M2: =F2+B2 -> 160222.86
A3: Dreghold | B3: 42223.454 | C3: ='Province Import (Ignore)'!I4 -> 13047830 | D3: =SUM(Cities!E14:E38) -> 210019 | E3: =C3-D3 -> 12837811 | F3: ='Provincial Economics'!D3-'Provincial Economics'!C3 -> -37872.045 | G3: ='New Retinues Summary'!S4 -> 2000 | H3: ='Knights Breakdown'!B3 -> 3066.8744 | I3: =SUM('Duchies Secret Sheet'!$C$4,'Duchies Secret Sheet'!$C21:$C$26) -> 26554.641 | J3: =IFERROR(__xludf.DUMMYFUNCTION("TO_TEXT(round(RANDBETWEEN(1000,10000)+(C3*0.005)))&TO_TEXT(round(RANDBETWEEN(1000,10000)-(C3*0.005)))"),"67842-62827") -> 67842-62827 | K3: =D3/C3 -> 0.016096086 | L3: =E3/C3 -> 0.98390391 | M3: =F3+B3 -> 4351.4094
A4: Madinglia | B4: 219681.69 | C4: ='Province Import (Ignore)'!I3 -> 3739211 | D4: =SUM(Cities!E39:E50) -> 72536 | E4: =C4-D4 -> 3666675 | F4: ='Provincial Economics'!D4-'Provincial Economics'!C4 -> 1164.8905 | G4: ='New Retinues Summary'!S5 -> 300 | H4: ='Knights Breakdown'!B4 -> 383.80462 | I4: =SUM('Duchies Secret Sheet'!$C$41:$C$45,'Duchies Secret Sheet'!$C$3) -> 0 | J4: =IFERROR(__xludf.DUMMYFUNCTION("TO_TEXT(round(RANDBETWEEN(1000,10000)+(C4*0.005)))&TO_TEXT(round(RANDBETWEEN(1000,10000)-(C4*0.005)))"),"21221-15914") -> 21221-15914 | K4: =D4/C4 -> 0.019398745 | L4: =E4/C4 -> 0.98060126 | M4: =F4+B4 -> 220846.58
A5: Ralim | B5: 185816.13 | C5: ='Province Import (Ignore)'!I7 -> 7694131 | D5: =SUM(Cities!E52:E63) -> 132591 | E5: =C5-D5 -> 7561540 | F5: ='Provincial Economics'!D5-'Provincial Economics'!C5 -> -26961.687 | G5: ='New Retinues Summary'!S6 -> 0 | H5: ='Knights Breakdown'!B5 -> 1353.2702 | I5: =SUM('Duchies Secret Sheet'!$C$6,'Duchies Secret Sheet'!$C$13:$C$15) -> 15833 | J5: =IFERROR(__xludf.DUMMYFUNCTION("TO_TEXT(round(RANDBETWEEN(1000,10000)+(C5*0.005)))&TO_TEXT(round(RANDBETWEEN(1000,10000)-(C5*0.005)))"),"43900-31918") -> 43900-31918 | K5: =D5/C5 -> 0.017232745 | L5: =E5/C5 -> 0.98276725 | M5: =F5+B5 -> 158854.44
A6: Sirong | B6: 76796.648 | C6: ='Province Import (Ignore)'!I6 -> 16040936 | D6: =SUM(Cities!E65:E104) -> 460501 | E6: =C6-D6 -> 15580435 | F6: ='Provincial Economics'!D6-'Provincial Economics'!C6 -> -76847.919 | G6: ='New Retinues Summary'!S7 -> 200 | H6: ='Knights Breakdown'!B6 -> 4214.3773 | I6: =SUM('Duchies Secret Sheet'!$C$5,'Duchies Secret Sheet'!$C$7:$C$12) -> 41000 | J6: =IFERROR(__xludf.DUMMYFUNCTION("TO_TEXT(round(RANDBETWEEN(1000,10000)+(C6*0.005)))&TO_TEXT(round(RANDBETWEEN(1000,10000)-(C6*0.005)))"),"85311-76707") -> 85311-76707 | K6: =D6/C6 -> 0.028707863 | L6: =E6/C6 -> 0.97129214 | M6: =F6+B6 -> -51.271419
A7: Swanhall | B7: 68991.167 | C7: ='Province Import (Ignore)'!I2 -> 17007036 | D7: =SUM(Cities!E105:E166) -> 579594 | E7: =C7-D7 -> 16427442 | F7: ='Provincial Economics'!D7-'Provincial Economics'!C7 -> -37545.637 | G7: ='New Retinues Summary'!S8 -> 0 | H7: ='Knights Breakdown'!B7 -> 5603.8644 | I7: =SUM('Duchies Secret Sheet'!$C$2,'Duchies Secret Sheet'!$C$27:$C$40) -> 21849.36 | J7: =IFERROR(__xludf.DUMMYFUNCTION("TO_TEXT(round(RANDBETWEEN(1000,10000)+(C7*0.005)))&TO_TEXT(round(RANDBETWEEN(1000,10000)-(C7*0.005)))"),"89956-82393") -> 89956-82393 | K7: =D7/C7 -> 0.03407966 | L7: =E7/C7 -> 0.96592034 | M7: =F7+B7 -> 31445.53
A8: Total | B8: =SUM(B2:B7) -> 794820.66 | C8: =SUM(C2:C7) -> 63727851 | D8: =SUM(D2:D7) -> 1667012 | E8: =SUM(E2:E7) -> 62060839 | F8: =SUM(F2:F7) -> -219151.12 | G8: =SUM(G2:G7) -> 2900 | H8: =SUM(H2:H7) -> 16564.439 | I8: =SUM(I2:I7) -> 131183 | J8: =SUM('Provincial Secret Sheet'!E1:E6) -> 302999.68 | M8: =SUM(M2:M7) -> 575669.54
A9: Average | B9: =AVERAGE(B2:B7) -> 132470.11 | C9: =AVERAGE(C2:C7) -> 10621308 | D9: =AVERAGE(D2:D7) -> 277835.33 | E9: =AVERAGE(E2:E7) -> 10343473 | F9: =AVERAGE(F2:F7) -> -36525.187 | G9: =AVERAGE(G2:G7) -> 483.33333 | H9: =AVERAGE(H2:H7) -> 2760.7398 | I9: =AVERAGE(I2:I7) -> 21863.833 | J9: =J8/6 -> 50499.946 | K9: =AVERAGE(K2:K7) -> 0.024946473 | L9: =AVERAGE(L2:L7) -> 0.97505353 | M9: =AVERAGE(M2:M7) -> 95944.923

Sheet Duchies Summary
A1: Duchy | B1: Capital | C1: Province | D1: Net Income | E1: Gold Kastars | F1: Raised Levies | G1: Possible Levies | H1: Urban Households | I1: Rural Households | J1: Total Population | K1: Urban Population | L1: Rural Population | M1: Urban% | N1: Rural% | O1: Knights | P1: Knight Tradition | Q1: Rural Knights | R1: Urban Knights | T1: Future Gold
A2: ='Duchies Import'!B:B -> Swanhall | B2: ='Duchies Import'!C:C -> Swanhall | C2: ='Ducal Economics'!B2 -> Swanhall | E2: 1 | F2: ='Duchies Secret Sheet'!C2:C45 -> 2949.3599 | G2: =IFERROR(__xludf.DUMMYFUNCTION("TO_TEXT(round(RANDBETWEEN(100,3000)+('Duchies Secret Sheet'!E2)))&TO_TEXT(round(RANDBETWEEN(100,1500)-('Duchies Secret Sheet'!E2)))"),"5569-2449") -> 5569-2449 | H2: =K2/3.5 -> 12258.571 | I2: =L2/3.5 -> 244303.14 | J2: ='Duchies Import'!I2 -> 897966 | K2: ='Duchies Import'!K2 -> 42905 | L2: ='Duchies Import'!J2 -> 855061 | M2: =K2/J2 -> 0.047780205 | N2: =L2/J2 -> 0.95221979 | O2: =Q2+R2 -> 342.6322 | P2: 0.8 | Q2: =L2*P2*0.00025 -> 171.0122 | R2: =P2*K2*0.005 -> 171.62 | T2: =E2+D2 -> 1
A3: ='Duchies Import'!B:B -> Slutiarm | B3: ='Duchies Import'!C:C -> Slutiarm | C3: ='Ducal Economics'!B3 -> Madinglia | E3: 1 | F3: ='Duchies Secret Sheet'!C3:C46 -> 0 | G3: =IFERROR(__xludf.DUMMYFUNCTION("TO_TEXT(round(RANDBETWEEN(100,3000)+('Duchies Secret Sheet'!E3)))&TO_TEXT(round(RANDBETWEEN(100,1500)-('Duchies Secret Sheet'!E3)))"),"3542-638") -> 3542-638 | H3: =K3/3.5 -> 6136 | I3: =L3/3.5 -> 79026 | J3: ='Duchies Import'!I3 -> 298067 | K3: ='Duchies Import'!K3 -> 21476 | L3: ='Duchies Import'!J3 -> 276591 | M3: =K3/J3 -> 0.072050915 | N3: =L3/J3 -> 0.92794909 | O3: =Q3+R3 -> 52.958325 | P3: 0.3 | Q3: =L3*P3*0.00025 -> 20.744325 | R3: =P3*K3*0.005 -> 32.214 | T3: =E3+D3 -> 1
A4: ='Duchies Import'!B:B -> Dreghold | B4: ='Duchies Import'!C:C -> Dreghold | C4: ='Ducal Economics'!B4 -> Dreghold | E4: 1 | F4: 2000 | G4: =IFERROR(__xludf.DUMMYFUNCTION("TO_TEXT(round(RANDBETWEEN(100,3000)+('Duchies Secret Sheet'!E4)))&TO_TEXT(round(RANDBETWEEN(100,1500)-('Duchies Secret Sheet'!E4)))"),"4633-2213") -> 4633-2213 | H4: =K4/3.5 -> 28761.714 | I4: =L4/3.5 -> 414572.86 | J4: ='Duchies Import'!I4 -> 1551671 | K4: ='Duchies Import'!K4 -> 100666 | L4: ='Duchies Import'!J4 -> 1451005 | M4: =K4/J4 -> 0.064875866 | N4: =L4/J4 -> 0.93512413 | O4: =Q4+R4 -> 623.5785 | P4: 0.72 | Q4: =L4*P4*0.00025 -> 261.1809 | R4: =P4*K4*0.005 -> 362.3976 | T4: =E4+D4 -> 1
A5: ='Duchies Import'!B:B -> Sirong | B5: ='Duchies Import'!C:C -> Sirong | C5: ='Ducal Economics'!B5 -> Sirong | D5: ='Ducal Economics'!C5-'Ducal Economics'!D5 -> -17003.811 | E5: -7034.2971 | F5: ='Duchies Secret Sheet'!C5:C48 -> 10000 | G5: =IFERROR(__xludf.DUMMYFUNCTION("TO_TEXT(round(RANDBETWEEN(100,3000)+('Duchies Secret Sheet'!E5)))&TO_TEXT(round(RANDBETWEEN(100,1500)-('Duchies Secret Sheet'!E5)))"),"13640-10136") -> 13640-10136 | H5: =K5/3.5 -> 16931.143 | I5: =L5/3.5 -> 629376.57 | J5: ='Duchies Import'!I5 -> 2262077 | K5: ='Duchies Import'!K5 -> 59259 | L5: ='Duchies Import'!J5 -> 2202818 | M5: =K5/J5 -> 0.026196721 | N5: =L5/J5 -> 0.97380328 | O5: =Q5+R5 -> 575.95966 | P5: 0.68 | Q5: =L5*P5*0.00025 -> 374.47906 | R5: =P5*K5*0.005 -> 201.4806 | T5: =E5+D5 -> -24038.108
A6: ='Duchies Import'!B:B -> Brookward | B6: ='Duchies Import'!C:C -> Brookward | C6: ='Ducal Economics'!B6 -> Ralim | E6: 1 | F6: ='Duchies Secret Sheet'!C6:C49 -> 6528 | G6: =IFERROR(__xludf.DUMMYFUNCTION("TO_TEXT(round(RANDBETWEEN(100,3000)+('Duchies Secret Sheet'!E6)))&TO_TEXT(round(RANDBETWEEN(100,1500)-('Duchies Secret Sheet'!E6)))"),"9182-5954") -> 9182-5954 | H6: =K6/3.5 -> 23154.571 | I6: =L6/3.5 -> 349852.86 | J6: ='Duchies Import'!I6 -> 1305527 | K6: ='Duchies Import'!K6 -> 81041 | L6: ='Duchies Import'!J6 -> 1224485 | M6: =K6/J6 -> 0.062075315 | N6: =L6/J6 -> 0.93792392 | O6: =Q6+R6 -> 377.00291 | P6: 0.53 | Q6: =L6*P6*0.00025 -> 162.24426 | R6: =P6*K6*0.005 -> 214.75865 | T6: =E6+D6 -> 1
A7: ='Duchies Import'!B:B -> Vhalian Marches | B7: ='Duchies Import'!C:C -> Vhalthin | C7: ='Ducal Economics'!B7 -> Sirong | E7: 1 | F7: ='Duchies Secret Sheet'!C7:C50 -> 20000 | G7: =IFERROR(__xludf.DUMMYFUNCTION("TO_TEXT(round(RANDBETWEEN(100,3000)+('Duchies Secret Sheet'!E7)))&TO_TEXT(round(RANDBETWEEN(100,1500)-('Duchies Secret Sheet'!E7)))"),"28820-26375") -> 28820-26375 | H7: =K7/3.5 -> 19134.571 | I7: =L7/3.5 -> 1549696.3 | J7: ='Duchies Import'!I7 -> 5490909 | K7: ='Duchies Import'!K7 -> 66971 | L7: ='Duchies Import'!J7 -> 5423937 | M7: =K7/J7 -> 0.012196705 | N7: =L7/J7 -> 0.98780311 | O7: =Q7+R7 -> 1149.7707 | P7: 0.68 | Q7: =L7*P7*0.00025 -> 922.06929 | R7: =P7*K7*0.005 -> 227.7014 | T7: =E7+D7 -> 1
A8: ='Duchies Import'!B:B -> Southern Shores | B8: ='Duchies Import'!C:C -> Alhas | C8: ='Ducal Economics'!B8 -> Sirong | D8: ='Ducal Economics'!C8-'Ducal Economics'!D8 -> -8550.6549 | E8: -955.89437 | F8: ='Duchies Secret Sheet'!C8:C51 -> 5000 | G8: =IFERROR(__xludf.DUMMYFUNCTION("TO_TEXT(round(RANDBETWEEN(100,3000)+('Duchies Secret Sheet'!E8)))&TO_TEXT(round(RANDBETWEEN(100,1500)-('Duchies Secret Sheet'!E8)))"),"8332-4977") -> 8332-4977 | H8: =K8/3.5 -> 9194 | I8: =L8/3.5 -> 340568 | J8: ='Duchies Import'!I8 -> 1224167 | K8: ='Duchies Import'!K8 -> 32179 | L8: ='Duchies Import'!J8 -> 1191988 | M8: =K8/J8 -> 0.026286446 | N8: =L8/J8 -> 0.97371355 | O8: =Q8+R8 -> 312.04656 | P8: 0.68 | Q8: =L8*P8*0.00025 -> 202.63796 | R8: =P8*K8*0.005 -> 109.4086 | T8: =E8+D8 -> -9506.5493
A9: ='Duchies Import'!B:B -> Dregsten Bay | B9: ='Duchies Import'!C:C -> Dryvaterga | C9: ='Ducal Economics'!B9 -> Sirong | D9: ='Ducal Economics'!C9-'Ducal Economics'!D9 -> 3227.3489 | E9: 7654.6979 | F9: ='Duchies Secret Sheet'!C9:C52 -> 0 | G9: =IFERROR(__xludf.DUMMYFUNCTION("TO_TEXT(round(RANDBETWEEN(100,3000)+('Duchies Secret Sheet'!E9)))&TO_TEXT(round(RANDBETWEEN(100,1500)-('Duchies Secret Sheet'!E9)))"),"11465-9705") -> 11465-9705 | H9: =K9/3.5 -> 18818.286 | I9: =L9/3.5 -> 601768.86 | J9: ='Duchies Import'!I9 -> 2172056 | K9: ='Duchies Import'!K9 -> 65864 | L9: ='Duchies Import'!J9 -> 2106191 | M9: =K9/J9 -> 0.030323343 | N9: =L9/J9 -> 0.9696762 | O9: =Q9+R9 -> 581.99007 | P9: 0.68 | Q9: =L9*P9*0.00025 -> 358.05247 | R9: =P9*K9*0.005 -> 223.9376 | T9: =E9+D9 -> 10882.047
A10: ='Duchies Import'!B:B -> Amber Shores | B10: ='Duchies Import'!C:C -> Amber Waters | C10: ='Ducal Economics'!B10 -> Sirong | D10: ='Ducal Economics'!C10-'Ducal Economics'!D10 -> 813.28075 | E10: 13319.527 | F10: ='Duchies Secret Sheet'!C10:C53 -> 0 | G10: =IFERROR(__xludf.DUMMYFUNCTION("TO_TEXT(round(RANDBETWEEN(100,3000)+('Duchies Secret Sheet'!E10)))&TO_TEXT(round(RANDBETWEEN(100,1500)-('Duchies Secret Sheet'!E10)))"),"5658-3243") -> 5658-3243 | H10: =K10/3.5 -> 2838.2857 | I10: =L10/3.5 -> 253476 | J10: ='Duchies Import'!I10 -> 897100 | K10: ='Duchies Import'!K10 -> 9934 | L10: ='Duchies Import'!J10 -> 887166 | M10: =K10/J10 -> 0.011073459 | N10: =L10/J10 -> 0.98892654 | O10: =Q10+R10 -> 184.59382 | P10: 0.68 | Q10: =L10*P10*0.00025 -> 150.81822 | R10: =P10*K10*0.005 -> 33.7756 | T10: =E10+D10 -> 14132.807
A11: ='Duchies Import'!B:B -> Griffin's Bay | B11: ='Duchies Import'!C:C -> Ulport | C11: ='Ducal Economics'!B11 -> Sirong | D11: ='Ducal Economics'!C11-'Ducal Economics'!D11 -> -9.0832771 | E11: 33918.251 | F11: ='Duchies Secret Sheet'!C11:C54 -> 2000 | G11: =IFERROR(__xludf.DUMMYFUNCTION("TO_TEXT(round(RANDBETWEEN(100,3000)+('Duchies Secret Sheet'!E11)))&TO_TEXT(round(RANDBETWEEN(100,1500)-('Duchies Secret Sheet'!E11)))"),"11397-10320") -> 11397-10320 | H11: =K11/3.5 -> 33452.857 | I11: =L11/3.5 -> 609732.29 | J11: ='Duchies Import'!I11 -> 2251148 | K11: ='Duchies Import'!K11 -> 117085 | L11: ='Duchies Import'!J11 -> 2134063 | M11: =K11/J11 -> 0.05201124 | N11: =L11/J11 -> 0.94798876 | O11: =Q11+R11 -> 760.87971 | P11: 0.68 | Q11: =L11*P11*0.00025 -> 362.79071 | R11: =P11*K11*0.005 -> 398.089 | T11: =E11+D11 -> 33909.167
A12: ='Duchies Import'!B:B -> Lesserlands | B12: ='Duchies Import'!C:C -> Sirongrasp | C12: ='Ducal Economics'!B12 -> Sirong | D12: ='Ducal Economics'!C12-'Ducal Economics'!D12 -> -6290.9465 | E12: 5381.4815 | F12: ='Duchies Secret Sheet'!C12:C55 -> 4000 | G12: =IFERROR(__xludf.DUMMYFUNCTION("TO_TEXT(round(RANDBETWEEN(100,3000)+('Duchies Secret Sheet'!E12)))&TO_TEXT(round(RANDBETWEEN(100,1500)-('Duchies Secret Sheet'!E12)))"),"10709-7423") -> 10709-7423 | H12: =K12/3.5 -> 8498.5714 | I12: =L12/3.5 -> 470965.43 | J12: ='Duchies Import'!I12 -> 1678124 | K12: ='Duchies Import'!K12 -> 29745 | L12: ='Duchies Import'!J12 -> 1648379 | M12: =K12/J12 -> 0.01772515 | N12: =L12/J12 -> 0.98227485 | O12: =Q12+R12 -> 381.35743 | P12: 0.68 | Q12: =L12*P12*0.00025 -> 280.22443 | R12: =P12*K12*0.005 -> 101.133 | T12: =E12+D12 -> -909.46496
A13: ='Duchies Import'!B:B -> ShadowWood | B13: ='Duchies Import'!C:C -> Shadowtown | C13: ='Ducal Economics'!B13 -> Ralim | D13: ='Ducal Economics'!C13-'Ducal Economics'!D13 -> -1090.5649 | E13: 12984.916 | F13: ='Duchies Secret Sheet'!C13:C56 -> 1200 | G13: =IFERROR(__xludf.DUMMYFUNCTION("TO_TEXT(round(RANDBETWEEN(100,3000)+('Duchies Secret Sheet'!E13)))&TO_TEXT(round(RANDBETWEEN(100,1500)-('Duchies Secret Sheet'!E13)))"),"10722-8888") -> 10722-8888 | H13: =K13/3.5 -> 616.85714 | I13: =L13/3.5 -> 582255.43 | J13: ='Duchies Import'!I13 -> 2040053 | K13: ='Duchies Import'!K13 -> 2159 | L13: ='Duchies Import'!J13 -> 2037894 | M13: =K13/J13 -> 0.0010583058 | N13: =L13/J13 -> 0.99894169 | O13: =Q13+R13 -> 275.7423 | P13: 0.53 | Q13: =L13*P13*0.00025 -> 270.02096 | R13: =P13*K13*0.005 -> 5.72135 | T13: =E13+D13 -> 11894.351
A14: ='Duchies Import'!B:B -> Mondwatch | B14: ='Duchies Import'!C:C -> Bear Hall | C14: ='Ducal Economics'!B14 -> Ralim | D14: ='Ducal Economics'!C14-'Ducal Economics'!D14 -> -4505.773 | E14: 13118.043 | F14: ='Duchies Secret Sheet'!C14:C57 -> 3405 | G14: =IFERROR(__xludf.DUMMYFUNCTION("TO_TEXT(round(RANDBETWEEN(100,3000)+('Duchies Secret Sheet'!E14)))&TO_TEXT(round(RANDBETWEEN(100,1500)-('Duchies Secret Sheet'!E14)))"),"10854-9114") -> 10854-9114 | H14: =K14/3.5 -> 10846.571 | I14: =L14/3.5 -> 590251.43 | J14: ='Duchies Import'!I14 -> 2103843 | K14: ='Duchies Import'!K14 -> 37963 | L14: ='Duchies Import'!J14 -> 2065880 | M14: =K14/J14 -> 0.018044597 | N14: =L14/J14 -> 0.9819554 | O14: =Q14+R14 -> 374.33105 | P14: 0.53 | Q14: =L14*P14*0.00025 -> 273.7291 | R14: =P14*K14*0.005 -> 100.60195 | T14: =E14+D14 -> 8612.2699
A15: ='Duchies Import'!B:B -> Ratermarch | B15: ='Duchies Import'!C:C -> Raterehall | C15: ='Ducal Economics'!B15 -> Ralim | D15: ='Ducal Economics'!C15-'Ducal Economics'!D15 -> -7564.9251 | E15: 3715.6737 | F15: ='Duchies Secret Sheet'!C15:C58 -> 4700 | G15: =IFERROR(__xludf.DUMMYFUNCTION("TO_TEXT(round(RANDBETWEEN(100,3000)+('Duchies Secret Sheet'!E15)))&TO_TEXT(round(RANDBETWEEN(100,1500)-('Duchies Secret Sheet'!E15)))"),"11643-9460") -> 11643-9460 | H15: =K15/3.5 -> 6225.7143 | I15: =L15/3.5 -> 611941.43 | J15: ='Duchies Import'!I15 -> 2163584 | K15: ='Duchies Import'!K15 -> 21790 | L15: ='Duchies Import'!J15 -> 2141795 | M15: =K15/J15 -> 0.010071252 | N15: =L15/J15 -> 0.98992921 | O15: =Q15+R15 -> 341.53134 | P15: 0.53 | Q15: =L15*P15*0.00025 -> 283.78784 | R15: =P15*K15*0.005 -> 57.7435 | T15: =E15+D15 -> -3849.2515
A16: ='Duchies Import'!B:B -> Vinh | B16: ='Duchies Import'!C:C -> Vinh | C16: ='Ducal Economics'!B16 -> Crownlands | D16: ='Ducal Economics'!C16-'Ducal Economics'!D16 -> -10656.278 | E16: -5976.5009 | F16: ='Duchies Secret Sheet'!C16:C59 -> 5995 | G16: =IFERROR(__xludf.DUMMYFUNCTION("TO_TEXT(round(RANDBETWEEN(100,3000)+('Duchies Secret Sheet'!E16)))&TO_TEXT(round(RANDBETWEEN(100,1500)-('Duchies Secret Sheet'!E16)))"),"8869-5829") -> 8869-5829 | H16: =K16/3.5 -> 6925.1429 | I16: =L16/3.5 -> 335663.71 | J16: ='Duchies Import'!I16 -> 1199062 | K16: ='Duchies Import'!K16 -> 24238 | L16: ='Duchies Import'!J16 -> 1174823 | M16: =K16/J16 -> 0.020214134 | N16: =L16/J16 -> 0.97978503 | O16: =Q16+R16 -> 315.32077 | P16: 0.76 | Q16: =L16*P16*0.00025 -> 223.21637 | R16: =P16*K16*0.005 -> 92.1044 | T16: =E16+D16 -> -16632.779
A17: ='Duchies Import'!B:B -> Drelme | B17: ='Duchies Import'!C:C -> Drelme | C17: ='Ducal Economics'!B17 -> Crownlands | D17: ='Ducal Economics'!C17-'Ducal Economics'!D17 -> -9277.997 | E17: -2041.9726 | F17: ='Duchies Secret Sheet'!C17:C60 -> 5390 | G17: =IFERROR(__xludf.DUMMYFUNCTION("TO_TEXT(round(RANDBETWEEN(100,3000)+('Duchies Secret Sheet'!E17)))&TO_TEXT(round(RANDBETWEEN(100,1500)-('Duchies Secret Sheet'!E17)))"),"6900-3954") -> 6900-3954 | H17: =K17/3.5 -> 9776.5714 | I17: =L17/3.5 -> 298210.57 | J17: ='Duchies Import'!I17 -> 1077956 | K17: ='Duchies Import'!K17 -> 34218 | L17: ='Duchies Import'!J17 -> 1043737 | M17: =K17/J17 -> 0.031743411 | N17: =L17/J17 -> 0.96825566 | O17: =Q17+R17 -> 328.33843 | P17: 0.76 | Q17: =L17*P17*0.00025 -> 198.31003 | R17: =P17*K17*0.005 -> 130.0284 | T17: =E17+D17 -> -11319.97
A18: ='Duchies Import'!B:B -> Oal's Reach | B18: ='Duchies Import'!C:C -> Oaledale | C18: ='Ducal Economics'!B18 -> Crownlands | D18: ='Ducal Economics'!C18-'Ducal Economics'!D18 -> -11058.497 | E18: -8672.4759 | F18: ='Duchies Secret Sheet'!C18:C61 -> 6061 | G18: =IFERROR(__xludf.DUMMYFUNCTION("TO_TEXT(round(RANDBETWEEN(100,3000)+('Duchies Secret Sheet'!E18)))&TO_TEXT(round(RANDBETWEEN(100,1500)-('Duchies Secret Sheet'!E18)))"),"6540-5589") -> 6540-5589 | H18: =K18/3.5 -> 7175.7143 | I18: =L18/3.5 -> 339148 | J18: ='Duchies Import'!I18 -> 1212133 | K18: ='Duchies Import'!K18 -> 25115 | L18: ='Duchies Import'!J18 -> 1187018 | M18: =K18/J18 -> 0.020719674 | N18: =L18/J18 -> 0.97928033 | O18: =Q18+R18 -> 320.97042 | P18: 0.76 | Q18: =L18*P18*0.00025 -> 225.53342 | R18: =P18*K18*0.005 -> 95.437 | T18: =E18+D18 -> -19730.973
A19: ='Duchies Import'!B:B -> Swiftme | B19: ='Duchies Import'!C:C -> Swiftme | C19: ='Ducal Economics'!B19 -> Crownlands | D19: ='Ducal Economics'!C19-'Ducal Economics'!D19 -> -12630.654 | E19: -2675.8862 | F19: ='Duchies Secret Sheet'!C19:C62 -> 7500 | G19: =IFERROR(__xludf.DUMMYFUNCTION("TO_TEXT(round(RANDBETWEEN(100,3000)+('Duchies Secret Sheet'!E19)))&TO_TEXT(round(RANDBETWEEN(100,1500)-('Duchies Secret Sheet'!E19)))"),"13124-11430") -> 13124-11430 | H19: =K19/3.5 -> 10590.857 | I19: =L19/3.5 -> 701065.14 | J19: ='Duchies Import'!I19 -> 2490796 | K19: ='Duchies Import'!K19 -> 37068 | L19: ='Duchies Import'!J19 -> 2453728 | M19: =K19/J19 -> 0.01488199 | N19: =L19/J19 -> 0.98511801 | O19: =Q19+R19 -> 607.06672 | P19: 0.76 | Q19: =L19*P19*0.00025 -> 466.20832 | R19: =P19*K19*0.005 -> 140.8584 | T19: =E19+D19 -> -15306.54
A20: ='Duchies Import'!B:B -> Heartwell | B20: ='Duchies Import'!C:C -> Heartwell | C20: ='Ducal Economics'!B20 -> Crownlands | D20: ='Ducal Economics'!C20-'Ducal Economics'!D20 -> 1783.8763 | E20: 30054.887 | F20: ='Duchies Secret Sheet'!C20:C63 -> 1000 | G20: =IFERROR(__xludf.DUMMYFUNCTION("TO_TEXT(round(RANDBETWEEN(100,3000)+('Duchies Secret Sheet'!E20)))&TO_TEXT(round(RANDBETWEEN(100,1500)-('Duchies Secret Sheet'!E20)))"),"2061-1136") -> 2061-1136 | H20: =K20/3.5 -> 28602.571 | I20: =L20/3.5 -> 75322 | J20: ='Duchies Import'!I20 -> 363736 | K20: ='Duchies Import'!K20 -> 100109 | L20: ='Duchies Import'!J20 -> 263627 | M20: =K20/J20 -> 0.27522434 | N20: =L20/J20 -> 0.72477566 | O20: =Q20+R20 -> 430.50333 | P20: 0.76 | Q20: =L20*P20*0.00025 -> 50.08913 | R20: =P20*K20*0.005 -> 380.4142 | T20: =E20+D20 -> 31838.763
A21: ='Duchies Import'!B:B -> Pearlpass | B21: ='Duchies Import'!C:C -> Pearlpass | C21: ='Ducal Economics'!B21 -> Dreghold | D21: ='Ducal Economics'!C21-'Ducal Economics'!D21 -> 2734.5408 | E21: 29600.767 | F21: ='Duchies Secret Sheet'!C21:C64 -> 0 | G21: =IFERROR(__xludf.DUMMYFUNCTION("TO_TEXT(round(RANDBETWEEN(100,3000)+('Duchies Secret Sheet'!E21)))&TO_TEXT(round(RANDBETWEEN(100,1500)-('Duchies Secret Sheet'!E21)))"),"7738-5184") -> 7738-5184 | H21: =K21/3.5 -> 6772.8571 | I21: =L21/3.5 -> 907391.14 | J21: ='Duchies Import'!I21 -> 3199574 | K21: ='Duchies Import'!K21 -> 23705 | L21: ='Duchies Import'!J21 -> 3175869 | M21: =K21/J21 -> 0.0074087988 | N21: =L21/J21 -> 0.9925912 | O21: =Q21+R21 -> 656.99442 | P21: 0.72 | Q21: =L21*P21*0.00025 -> 571.65642 | R21: =P21*K21*0.005 -> 85.338 | T21: =E21+D21 -> 32335.308
A22: ='Duchies Import'!B:B -> Prince's Boot | B22: ='Duchies Import'!C:C -> Draven | C22: ='Ducal Economics'!B22 -> Dreghold | D22: ='Ducal Economics'!C22-'Ducal Economics'!D22 -> 1000.5227 | E22: 1510.704 | F22: ='Duchies Secret Sheet'!C22:C65 -> 0 | G22: =IFERROR(__xludf.DUMMYFUNCTION("TO_TEXT(round(RANDBETWEEN(100,3000)+('Duchies Secret Sheet'!E22)))&TO_TEXT(round(RANDBETWEEN(100,1500)-('Duchies Secret Sheet'!E22)))"),"9291-6575") -> 9291-6575 | H22: =K22/3.5 -> 933.71429 | I22: =L22/3.5 -> 429714.86 | J22: ='Duchies Import'!I22 -> 1507269 | K22: ='Duchies Import'!K22 -> 3268 | L22: ='Duchies Import'!J22 -> 1504002 | M22: =K22/J22 -> 0.0021681598 | N22: =L22/J22 -> 0.9978325 | O22: =Q22+R22 -> 282.48516 | P22: 0.72 | Q22: =L22*P22*0.00025 -> 270.72036 | R22: =P22*K22*0.005 -> 11.7648 | T22: =E22+D22 -> 2511.2267
A23: ='Duchies Import'!B:B -> Swan's Reach | B23: ='Duchies Import'!C:C -> Swangeld | C23: ='Ducal Economics'!B23 -> Dreghold | D23: ='Ducal Economics'!C23-'Ducal Economics'!D23 -> -6234.1524 | E23: -6741.7716 | F23: ='Duchies Secret Sheet'!C23:C66 -> 4300 | G23: =IFERROR(__xludf.DUMMYFUNCTION("TO_TEXT(round(RANDBETWEEN(100,3000)+('Duchies Secret Sheet'!E23)))&TO_TEXT(round(RANDBETWEEN(100,1500)-('Duchies Secret Sheet'!E23)))"),"15557-11934") -> 15557-11934 | H23: =K23/3.5 -> 8056 | I23: =L23/3.5 -> 799389.43 | J23: ='Duchies Import'!I23 -> 2826059 | K23: ='Duchies Import'!K23 -> 28196 | L23: ='Duchies Import'!J23 -> 2797863 | M23: =K23/J23 -> 0.0099771449 | N23: =L23/J23 -> 0.99002286 | O23: =Q23+R23 -> 605.12094 | P23: 0.72 | Q23: =L23*P23*0.00025 -> 503.61534 | R23: =P23*K23*0.005 -> 101.5056 | T23: =E23+D23 -> -12975.924
A24: ='Duchies Import'!B:B -> Malhold | B24: ='Duchies Import'!C:C -> Malhold | C24: ='Ducal Economics'!B24 -> Dreghold | D24: ='Ducal Economics'!C24-'Ducal Economics'!D24 -> -11576.388 | E24: 2601.3103 | F24: ='Duchies Secret Sheet'!C24:C67 -> 6974 | G24: =IFERROR(__xludf.DUMMYFUNCTION("TO_TEXT(round(RANDBETWEEN(100,3000)+('Duchies Secret Sheet'!E24)))&TO_TEXT(round(RANDBETWEEN(100,1500)-('Duchies Secret Sheet'!E24)))"),"7127-6081") -> 7127-6081 | H24: =K24/3.5 -> 25764.286 | I24: =L24/3.5 -> 372775.71 | J24: ='Duchies Import'!I24 -> 1394890 | K24: ='Duchies Import'!K24 -> 90175 | L24: ='Duchies Import'!J24 -> 1304715 | M24: =K24/J24 -> 0.064646675 | N24: =L24/J24 -> 0.93535333 | O24: =Q24+R24 -> 559.4787 | P24: 0.72 | Q24: =L24*P24*0.00025 -> 234.8487 | R24: =P24*K24*0.005 -> 324.63 | T24: =E24+D24 -> -8975.0774
A25: ='Duchies Import'!B:B -> Westleden | B25: ='Duchies Import'!C:C -> Westleden | C25: ='Ducal Economics'!B25 -> Dreghold | D25: ='Ducal Economics'!C25-'Ducal Economics'!D25 -> -12110.879 | E25: -8193.1111 | F25: ='Duchies Secret Sheet'!C25:C68 -> 6600 | G25: =IFERROR(__xludf.DUMMYFUNCTION("TO_TEXT(round(RANDBETWEEN(100,3000)+('Duchies Secret Sheet'!E25)))&TO_TEXT(round(RANDBETWEEN(100,1500)-('Duchies Secret Sheet'!E25)))"),"8700-5305") -> 8700-5305 | H25: =K25/3.5 -> 5765.7143 | I25: =L25/3.5 -> 372313.71 | J25: ='Duchies Import'!I25 -> 1323278 | K25: ='Duchies Import'!K25 -> 20180 | L25: ='Duchies Import'!J25 -> 1303098 | M25: =K25/J25 -> 0.015250008 | N25: =L25/J25 -> 0.98474999 | O25: =Q25+R25 -> 307.20564 | P25: 0.72 | Q25: =L25*P25*0.00025 -> 234.55764 | R25: =P25*K25*0.005 -> 72.648 | T25: =E25+D25 -> -20303.99
A26: ='Duchies Import'!B:B -> Shurestar | B26: ='Duchies Import'!C:C -> Shurestar | C26: ='Ducal Economics'!B26 -> Dreghold | D26: ='Ducal Economics'!C26-'Ducal Economics'!D26 -> -10487.884 | E26: -2954.3171 | F26: ='Duchies Secret Sheet'!C26:C69 -> 5992 | G26: =IFERROR(__xludf.DUMMYFUNCTION("TO_TEXT(round(RANDBETWEEN(100,3000)+('Duchies Secret Sheet'!E26)))&TO_TEXT(round(RANDBETWEEN(100,1500)-('Duchies Secret Sheet'!E26)))"),"7300-5738") -> 7300-5738 | H26: =K26/3.5 -> 12832.286 | I26: =L26/3.5 -> 329549.71 | J26: ='Duchies Import'!I26 -> 1198337 | K26: ='Duchies Import'!K26 -> 44913 | L26: ='Duchies Import'!J26 -> 1153424 | M26: =K26/J26 -> 0.03747944 | N26: =L26/J26 -> 0.96252056 | O26: =Q26+R26 -> 369.30312 | P26: 0.72 | Q26: =L26*P26*0.00025 -> 207.61632 | R26: =P26*K26*0.005 -> 161.6868 | T26: =E26+D26 -> -13442.201
A27: ='Duchies Import'!B:B -> Raven's Reach | B27: ='Duchies Import'!C:C -> Westle | C27: ='Ducal Economics'!B27 -> Swanhall | D27: ='Ducal Economics'!C27-'Ducal Economics'!D27 -> 2419.92 | E27: 27779.28 | F27: ='Duchies Secret Sheet'!C27:C70 -> 0 | G27: =IFERROR(__xludf.DUMMYFUNCTION("TO_TEXT(round(RANDBETWEEN(100,3000)+('Duchies Secret Sheet'!E27)))&TO_TEXT(round(RANDBETWEEN(100,1500)-('Duchies Secret Sheet'!E27)))"),"11613-8176") -> 11613-8176 | H27: =K27/3.5 -> 11928 | I27: =L27/3.5 -> 527581.71 | J27: ='Duchies Import'!I27 -> 1888284 | K27: ='Duchies Import'!K27 -> 41748 | L27: ='Duchies Import'!J27 -> 1846536 | M27: =K27/J27 -> 0.022108962 | N27: =L27/J27 -> 0.97789104 | O27: =Q27+R27 -> 536.2992 | P27: 0.8 | Q27: =L27*P27*0.00025 -> 369.3072 | R27: =P27*K27*0.005 -> 166.992 | T27: =E27+D27 -> 30199.2
A28: ='Duchies Import'!B:B -> Northfold | B28: ='Duchies Import'!C:C -> Northfold Manor | C28: ='Ducal Economics'!B28 -> Swanhall | D28: ='Ducal Economics'!C28-'Ducal Economics'!D28 -> 782.41535 | E28: 13041.738 | F28: ='Duchies Secret Sheet'!C28:C71 -> 0 | G28: =IFERROR(__xludf.DUMMYFUNCTION("TO_TEXT(round(RANDBETWEEN(100,3000)+('Duchies Secret Sheet'!E28)))&TO_TEXT(round(RANDBETWEEN(100,1500)-('Duchies Secret Sheet'!E28)))"),"5000-1613") -> 5000-1613 | H28: =K28/3.5 -> 6694.2857 | I28: =L28/3.5 -> 121411.14 | J28: ='Duchies Import'!I28 -> 448368 | K28: ='Duchies Import'!K28 -> 23430 | L28: ='Duchies Import'!J28 -> 424939 | M28: =K28/J28 -> 0.052256182 | N28: =L28/J28 -> 0.94774605 | O28: =Q28+R28 -> 178.7078 | P28: 0.8 | Q28: =L28*P28*0.00025 -> 84.9878 | R28: =P28*K28*0.005 -> 93.72 | T28: =E28+D28 -> 13824.154
A29: ='Duchies Import'!B:B -> Blackstone | B29: ='Duchies Import'!C:C -> Anhelm | C29: ='Ducal Economics'!B29 -> Swanhall | D29: ='Ducal Economics'!C29-'Ducal Economics'!D29 -> 2985.575 | E29: 32870.175 | F29: ='Duchies Secret Sheet'!C29:C72 -> 0 | G29: =IFERROR(__xludf.DUMMYFUNCTION("TO_TEXT(round(RANDBETWEEN(100,3000)+('Duchies Secret Sheet'!E29)))&TO_TEXT(round(RANDBETWEEN(100,1500)-('Duchies Secret Sheet'!E29)))"),"11584-9048") -> 11584-9048 | H29: =K29/3.5 -> 16136.571 | I29: =L29/3.5 -> 585954 | J29: ='Duchies Import'!I29 -> 2107318 | K29: ='Duchies Import'!K29 -> 56478 | L29: ='Duchies Import'!J29 -> 2050839 | M29: =K29/J29 -> 0.026800891 | N29: =L29/J29 -> 0.97319863 | O29: =Q29+R29 -> 636.0798 | P29: 0.8 | Q29: =L29*P29*0.00025 -> 410.1678 | R29: =P29*K29*0.005 -> 225.912 | T29: =E29+D29 -> 35855.75
A30: ='Duchies Import'!B:B -> Ravenmark | B30: ='Duchies Import'!C:C -> Blackfeather Hall | C30: ='Ducal Economics'!B30 -> Swanhall | D30: ='Ducal Economics'!C30-'Ducal Economics'!D30 -> 1082.1621 | E30: 15739.459 | F30: ='Duchies Secret Sheet'!C30:C73 -> 0 | G30: =IFERROR(__xludf.DUMMYFUNCTION("TO_TEXT(round(RANDBETWEEN(100,3000)+('Duchies Secret Sheet'!E30)))&TO_TEXT(round(RANDBETWEEN(100,1500)-('Duchies Secret Sheet'!E30)))"),"4411-2724") -> 4411-2724 | H30: =K30/3.5 -> 7136.2857 | I30: =L30/3.5 -> 225574 | J30: ='Duchies Import'!I30 -> 814486 | K30: ='Duchies Import'!K30 -> 24977 | L30: ='Duchies Import'!J30 -> 789509 | M30: =K30/J30 -> 0.030665966 | N30: =L30/J30 -> 0.96933403 | O30: =Q30+R30 -> 257.8098 | P30: 0.8 | Q30: =L30*P30*0.00025 -> 157.9018 | R30: =P30*K30*0.005 -> 99.908 | T30: =E30+D30 -> 16821.621
A31: ='Duchies Import'!B:B -> Wet Shoor | B31: ='Duchies Import'!C:C -> Shaterse | C31: ='Ducal Economics'!B31 -> Swanhall | D31: ='Ducal Economics'!C31-'Ducal Economics'!D31 -> 718.66886 | E31: 12468.02 | F31: ='Duchies Secret Sheet'!C31:C74 -> 0 | G31: =IFERROR(__xludf.DUMMYFUNCTION("TO_TEXT(round(RANDBETWEEN(100,3000)+('Duchies Secret Sheet'!E31)))&TO_TEXT(round(RANDBETWEEN(100,1500)-('Duchies Secret Sheet'!E31)))"),"6819-4762") -> 6819-4762 | H31: =K31/3.5 -> 4313.1429 | I31: =L31/3.5 -> 317570 | J31: ='Duchies Import'!I31 -> 1126591 | K31: ='Duchies Import'!K31 -> 15096 | L31: ='Duchies Import'!J31 -> 1111495 | M31: =K31/J31 -> 0.013399716 | N31: =L31/J31 -> 0.98660028 | O31: =Q31+R31 -> 282.683 | P31: 0.8 | Q31: =L31*P31*0.00025 -> 222.299 | R31: =P31*K31*0.005 -> 60.384 | T31: =E31+D31 -> 13186.689
A32: ='Duchies Import'!B:B -> Quickwatch | B32: ='Duchies Import'!C:C -> Quickwatch | C32: ='Ducal Economics'!B32 -> Swanhall | D32: ='Ducal Economics'!C32-'Ducal Economics'!D32 -> 2138.9188 | E32: 25250.269 | F32: ='Duchies Secret Sheet'!C32:C75 -> 0 | G32: =IFERROR(__xludf.DUMMYFUNCTION("TO_TEXT(round(RANDBETWEEN(100,3000)+('Duchies Secret Sheet'!E32)))&TO_TEXT(round(RANDBETWEEN(100,1500)-('Duchies Secret Sheet'!E32)))"),"13409-10257") -> 13409-10257 | H32: =K32/3.5 -> 13266.286 | I32: =L32/3.5 -> 591470.29 | J32: ='Duchies Import'!I32 -> 2116578 | K32: ='Duchies Import'!K32 -> 46432 | L32: ='Duchies Import'!J32 -> 2070146 | M32: =K32/J32 -> 0.021937297 | N32: =L32/J32 -> 0.9780627 | O32: =Q32+R32 -> 599.7572 | P32: 0.8 | Q32: =L32*P32*0.00025 -> 414.0292 | R32: =P32*K32*0.005 -> 185.728 | T32: =E32+D32 -> 27389.188
A33: ='Duchies Import'!B:B -> The Deepwood | B33: ='Duchies Import'!C:C -> Deepmoor | C33: ='Ducal Economics'!B33 -> Swanhall | D33: ='Ducal Economics'!C33-'Ducal Economics'!D33 -> 1601.8739 | E33: 20416.865 | F33: ='Duchies Secret Sheet'!C33:C76 -> 0 | G33: =IFERROR(__xludf.DUMMYFUNCTION("TO_TEXT(round(RANDBETWEEN(100,3000)+('Duchies Secret Sheet'!E33)))&TO_TEXT(round(RANDBETWEEN(100,1500)-('Duchies Secret Sheet'!E33)))"),"6122-3429") -> 6122-3429 | H33: =K33/3.5 -> 10368.571 | I33: =L33/3.5 -> 234896.57 | J33: ='Duchies Import'!I33 -> 858428 | K33: ='Duchies Import'!K33 -> 36290 | L33: ='Duchies Import'!J33 -> 822138 | M33: =K33/J33 -> 0.042274949 | N33: =L33/J33 -> 0.95772505 | O33: =Q33+R33 -> 309.5876 | P33: 0.8 | Q33: =L33*P33*0.00025 -> 164.4276 | R33: =P33*K33*0.005 -> 145.16 | T33: =E33+D33 -> 22018.739
A34: ='Duchies Import'!B:B -> Swan's Shoor | B34: ='Duchies Import'!C:C -> Swan's Shoor | C34: ='Ducal Economics'!B34 -> Swanhall | D34: ='Ducal Economics'!C34-'Ducal Economics'!D34 -> -7670.9128 | E34: 16961.785 | F34: ='Duchies Secret Sheet'!C34:C77 -> 5000 | G34: =IFERROR(__xludf.DUMMYFUNCTION("TO_TEXT(round(RANDBETWEEN(100,3000)+('Duchies Secret Sheet'!E34)))&TO_TEXT(round(RANDBETWEEN(100,1500)-('Duchies Secret Sheet'!E34)))"),"6366-3768") -> 6366-3768 | H34: =K34/3.5 -> 20429.714 | I34: =L34/3.5 -> 270154.57 | J34: ='Duchies Import'!I34 -> 1017045 | K34: ='Duchies Import'!K34 -> 71504 | L34: ='Duchies Import'!J34 -> 945541 | M34: =K34/J34 -> 0.07030564 | N34: =L34/J34 -> 0.92969436 | O34: =Q34+R34 -> 475.1242 | P34: 0.8 | Q34: =L34*P34*0.00025 -> 189.1082 | R34: =P34*K34*0.005 -> 286.016 | T34: =E34+D34 -> 9290.8724
A35: ='Duchies Import'!B:B -> The Shield | B35: ='Duchies Import'!C:C -> The Shield | C35: ='Ducal Economics'!B35 -> Swanhall | D35: ='Ducal Economics'!C35-'Ducal Economics'!D35 -> 1735.0813 | E35: 21615.732 | F35: ='Duchies Secret Sheet'!C35:C78 -> 0 | G35: =IFERROR(__xludf.DUMMYFUNCTION("TO_TEXT(round(RANDBETWEEN(100,3000)+('Duchies Secret Sheet'!E35)))&TO_TEXT(round(RANDBETWEEN(100,1500)-('Duchies Secret Sheet'!E35)))"),"6663-5391") -> 6663-5391 | H35: =K35/3.5 -> 9838.5714 | I35: =L35/3.5 -> 358161.71 | J35: ='Duchies Import'!I35 -> 1288001 | K35: ='Duchies Import'!K35 -> 34435 | L35: ='Duchies Import'!J35 -> 1253566 | M35: =K35/J35 -> 0.026735228 | N35: =L35/J35 -> 0.97326477 | O35: =Q35+R35 -> 388.4532 | P35: 0.8 | Q35: =L35*P35*0.00025 -> 250.7132 | R35: =P35*K35*0.005 -> 137.74 | T35: =E35+D35 -> 23350.813
A36: ='Duchies Import'!B:B -> Elreach | B36: ='Duchies Import'!C:C -> Elreach | C36: ='Ducal Economics'!B36 -> Swanhall | D36: ='Ducal Economics'!C36-'Ducal Economics'!D36 -> 1678.5852 | E36: 21107.267 | F36: ='Duchies Secret Sheet'!C36:C79 -> 0 | G36: =IFERROR(__xludf.DUMMYFUNCTION("TO_TEXT(round(RANDBETWEEN(100,3000)+('Duchies Secret Sheet'!E36)))&TO_TEXT(round(RANDBETWEEN(100,1500)-('Duchies Secret Sheet'!E36)))"),"7735-6755") -> 7735-6755 | H36: =K36/3.5 -> 12170.857 | I36: =L36/3.5 -> 419140.57 | J36: ='Duchies Import'!I36 -> 1509590 | K36: ='Duchies Import'!K36 -> 42598 | L36: ='Duchies Import'!J36 -> 1466992 | M36: =K36/J36 -> 0.028218258 | N36: =L36/J36 -> 0.97178174 | O36: =Q36+R36 -> 463.7904 | P36: 0.8 | Q36: =L36*P36*0.00025 -> 293.3984 | R36: =P36*K36*0.005 -> 170.392 | T36: =E36+D36 -> 22785.852
A37: ='Duchies Import'!B:B -> Mightkeep | B37: ='Duchies Import'!C:C -> Mightkeep | C37: ='Ducal Economics'!B37 -> Swanhall | D37: ='Ducal Economics'!C37-'Ducal Economics'!D37 -> -8242.7007 | E37: 19815.693 | F37: ='Duchies Secret Sheet'!C37:C80 -> 5500 | G37: =IFERROR(__xludf.DUMMYFUNCTION("TO_TEXT(round(RANDBETWEEN(100,3000)+('Duchies Secret Sheet'!E37)))&TO_TEXT(round(RANDBETWEEN(100,1500)-('Duchies Secret Sheet'!E37)))"),"5824-4504") -> 5824-4504 | H37: =K37/3.5 -> 25851.714 | I37: =L37/3.5 -> 293600.57 | J37: ='Duchies Import'!I37 -> 1118082 | K37: ='Duchies Import'!K37 -> 90481 | L37: ='Duchies Import'!J37 -> 1027602 | M37: =K37/J37 -> 0.080925192 | N37: =L37/J37 -> 0.9190757 | O37: =Q37+R37 -> 567.4444 | P37: 0.8 | Q37: =L37*P37*0.00025 -> 205.5204 | R37: =P37*K37*0.005 -> 361.924 | T37: =E37+D37 -> 11572.993
A38: ='Duchies Import'!B:B -> Mightfall | B38: ='Duchies Import'!C:C -> Mightfall | C38: ='Ducal Economics'!B38 -> Swanhall | D38: ='Ducal Economics'!C38-'Ducal Economics'!D38 -> -8599.2328 | E38: 8606.9052 | F38: ='Duchies Secret Sheet'!C38:C81 -> 5000 | G38: =IFERROR(__xludf.DUMMYFUNCTION("TO_TEXT(round(RANDBETWEEN(100,3000)+('Duchies Secret Sheet'!E38)))&TO_TEXT(round(RANDBETWEEN(100,1500)-('Duchies Secret Sheet'!E38)))"),"7553-4744") -> 7553-4744 | H38: =K38/3.5 -> 11254.857 | I38: =L38/3.5 -> 294712.29 | J38: ='Duchies Import'!I38 -> 1070885 | K38: ='Duchies Import'!K38 -> 39392 | L38: ='Duchies Import'!J38 -> 1031493 | M38: =K38/J38 -> 0.036784529 | N38: =L38/J38 -> 0.96321547 | O38: =Q38+R38 -> 363.8666 | P38: 0.8 | Q38: =L38*P38*0.00025 -> 206.2986 | R38: =P38*K38*0.005 -> 157.568 | T38: =E38+D38 -> 7.6724286
A39: ='Duchies Import'!B:B -> Eguard | B39: ='Duchies Import'!C:C -> Eguard | C39: ='Ducal Economics'!B39 -> Swanhall | D39: ='Ducal Economics'!C39-'Ducal Economics'!D39 -> -5163.021 | E39: 13932.811 | F39: ='Duchies Secret Sheet'!C39:C82 -> 3400 | G39: =IFERROR(__xludf.DUMMYFUNCTION("TO_TEXT(round(RANDBETWEEN(100,3000)+('Duchies Secret Sheet'!E39)))&TO_TEXT(round(RANDBETWEEN(100,1500)-('Duchies Secret Sheet'!E39)))"),"6122-2125") -> 6122-2125 | H39: =K39/3.5 -> 10153.714 | I39: =L39/3.5 -> 189582.57 | J39: ='Duchies Import'!I39 -> 699077 | K39: ='Duchies Import'!K39 -> 35538 | L39: ='Duchies Import'!J39 -> 663539 | M39: =K39/J39 -> 0.050835602 | N39: =L39/J39 -> 0.9491644 | O39: =Q39+R39 -> 274.8598 | P39: 0.8 | Q39: =L39*P39*0.00025 -> 132.7078 | R39: =P39*K39*0.005 -> 142.152 | T39: =E39+D39 -> 8769.7896
A40: ='Duchies Import'!B:B -> Lonely Light | B40: ='Duchies Import'!C:C -> Lonely Light | C40: ='Ducal Economics'!B40 -> Swanhall | D40: ='Ducal Economics'!C40-'Ducal Economics'!D40 -> 246.94898 | E40: 8222.5408 | F40: ='Duchies Secret Sheet'!C40:C83 -> 0 | G40: =IFERROR(__xludf.DUMMYFUNCTION("TO_TEXT(round(RANDBETWEEN(100,3000)+('Duchies Secret Sheet'!E40)))&TO_TEXT(round(RANDBETWEEN(100,1000)-('Duchies Secret Sheet'!E40)))"),"2080176") -> 2080176 | H40: =K40/3.5 -> 2473.1429 | I40: =L40/3.5 -> 14642.286 | J40: ='Duchies Import'!I40 -> 59904 | K40: ='Duchies Import'!K40 -> 8656 | L40: ='Duchies Import'!J40 -> 51248 | M40: =K40/J40 -> 0.14449786 | N40: =L40/J40 -> 0.85550214 | O40: =Q40+R40 -> 44.8736 | P40: 0.8 | Q40: =L40*P40*0.00025 -> 10.2496 | R40: =P40*K40*0.005 -> 34.624 | T40: =E40+D40 -> 8469.4898
...

Sheet Knights Breakdown
B1: Knights | C1: Knight Tradition | D1: Knight Wages | E1: Urban Population | F1: Urban Modifier | G1: Urban Knights | H1: Rural Population | I1: Rural Modifier | J1: Rural Knights
A2: Crownlands | B2: =(G2+J2) -> 1942.2476 | C2: 0.76 | D2: =B2*1.25 -> 2427.8095 | E2: ='New Provinces Summary'!D2 -> 211771 | F2: 0.005 | G2: =F2*E2*C2 -> 804.7298 | H2: ='New Provinces Summary'!E2 -> 5986936 | I2: 0.00025 | J2: =H2*I2*C2 -> 1137.5178
A3: Dreghold | B3: =(G3+J3) -> 3066.8744 | C3: 0.72 | D3: =B3*1.25 -> 3833.593 | E3: ='New Provinces Summary'!D3 -> 210019 | F3: =F2 -> 0.005 | G3: =F3*E3*C3 -> 756.0684 | H3: ='New Provinces Summary'!E3 -> 12837811 | I3: 0.00025 | J3: =H3*I3*C3 -> 2310.806
A4: Madinglia | B4: =(G4+J4) -> 383.80462 | C4: 0.3 | D4: =B4*1.25 -> 479.75578 | E4: ='New Provinces Summary'!D4 -> 72536 | F4: =F3 -> 0.005 | G4: =F4*E4*C4 -> 108.804 | H4: ='New Provinces Summary'!E4 -> 3666675 | I4: 0.00025 | J4: =H4*I4*C4 -> 275.00063
A5: Ralim | B5: =(G5+J5) -> 1353.2702 | C5: 0.53 | D5: =B5*1.25 -> 1691.5878 | E5: ='New Provinces Summary'!D5 -> 132591 | F5: =F4 -> 0.005 | G5: =F5*E5*C5 -> 351.36615 | H5: ='New Provinces Summary'!E5 -> 7561540 | I5: 0.00025 | J5: =H5*I5*C5 -> 1001.9041
A6: Sirong | B6: =(G6+J6) -> 4214.3773 | C6: 0.68 | D6: =B6*1.25 -> 5267.9717 | E6: ='New Provinces Summary'!D6 -> 460501 | F6: =F5 -> 0.005 | G6: =F6*E6*C6 -> 1565.7034 | H6: ='New Provinces Summary'!E6 -> 15580435 | I6: 0.00025 | J6: =H6*I6*C6 -> 2648.6739
A7: Swanhall | B7: =(G7+J7) -> 5603.8644 | C7: 0.8 | D7: =B7*1.25 -> 7004.8305 | E7: ='New Provinces Summary'!D7 -> 579594 | F7: =F6 -> 0.005 | G7: =F7*E7*C7 -> 2318.376 | H7: ='New Provinces Summary'!E7 -> 16427442 | I7: 0.00025 | J7: =H7*I7*C7 -> 3285.4884

Sheet Character Index
A1: Name | B1: House | C1: Current Age | D1: Age at Start | E1: Age at Death | F1: Status | G1: Years Since Start | H1: Age if Alive | I1: Intrigue | J1: Combat | K1: Diplomacy | L1: Stewardship | M1: Average Skill | N1: Birth Year | O1: Current Year | P1: Death Year
A2: Gabren | B2: Princeps | C2: =IF(F2="Alive",D2+G2," ") | D2: 18 | E2: 20 | F2: Dead | G2: 5 | H2: =IF(F2="Dead",G2+D2," ") -> 23 | I2: 60 | J2: 40 | K2: 60 | L2: 35 | M2: =IF(SUM(I2:L2)>0,AVERAGE(I2:L2)," ") -> 48.75 | N2: =O2-G2-D2 -> 1166 | O2: 1189 | P2: =IF(E2>0, N2+E2,"") -> 1186
A3: Armin | B3: Princeps | C3: =IF(F3="Alive",D3+G3," ") | D3: 17 | E3: 21 | F3: Dead | G3: 5 | H3: =IF(F3="Dead",G3+D3," ") -> 22 | I3: 35 | J3: 125 | K3: 50 | L3: 40 | M3: =IF(SUM(I3:L3)>0,AVERAGE(I3:L3)," ") -> 62.5 | N3: =O3-G3-D3 -> 1167 | O3: 1189 | P3: =IF(E3>0, N3+E3,"") -> 1188
A4: Frederick | B4: Senton | C4: =IF(F4="Alive",D4+G4," ") | D4: 43 | E4: 43 | F4: Dead | G4: 5 | H4: =IF(F4="Dead",G4+D4," ") -> 48 | M4: =IF(SUM(I4:L4)>0,AVERAGE(I4:L4)," ") | N4: =O4-G4-D4 -> 1141 | O4: 1189 | P4: =IF(E4>0, N4+E4,"") -> 1184
A5: Marian | B5: Senton | C5: =IF(F5="Alive",D5+G5," ") -> 43 | D5: 38 | F5: Alive | G5: 5 | H5: =IF(F5="Dead",G5+D5," ") | M5: =IF(SUM(I5:L5)>0,AVERAGE(I5:L5)," ") | N5: =O5-G5-D5 -> 1146 | O5: 1189 | P5: =IF(E5>0, N5+E5,"")
A6: John | B6: Senton | C6: =IF(F6="Alive",D6+G6," ") | D6: 22 | E6: 25 | F6: Dead | G6: 5 | H6: =IF(F6="Dead",G6+D6," ") -> 27 | I6: 65 | J6: 45 | K6: 90 | L6: 80 | M6: =IF(SUM(I6:L6)>0,AVERAGE(I6:L6)," ") -> 70 | N6: =O6-G6-D6 -> 1162 | O6: 1189 | P6: =IF(E6>0, N6+E6,"") -> 1187
A7: Jory | B7: Senton | C7: =IF(F7="Alive",D7+G7," ") -> 22 | D7: 17 | F7: Alive | G7: 5 | H7: =IF(F7="Dead",G7+D7," ") | I7: 35 | J7: 110 | K7: 80 | L7: 40 | M7: =IF(SUM(I7:L7)>0,AVERAGE(I7:L7)," ") -> 66.25 | N7: =O7-G7-D7 -> 1167 | O7: 1189 | P7: =IF(E7>0, N7+E7,"")
A8: Jason | B8: Senton | C8: =IF(F8="Alive",D8+G8," ") -> 20 | D8: 15 | F8: Alive | G8: 5 | H8: =IF(F8="Dead",G8+D8," ") | I8: 50 | J8: 90 | K8: 65 | L8: 45 | M8: =IF(SUM(I8:L8)>0,AVERAGE(I8:L8)," ") -> 62.5 | N8: =O8-G8-D8 -> 1169 | O8: 1189 | P8: =IF(E8>0, N8+E8,"")
A9: Jenny | B9: Senton | C9: =IF(F9="Alive",D9+G9," ") -> 17 | D9: 12 | F9: Alive | G9: 5 | H9: =IF(F9="Dead",G9+D9," ") | M9: =IF(SUM(I9:L9)>0,AVERAGE(I9:L9)," ") | N9: =O9-G9-D9 -> 1172 | O9: 1189 | P9: =IF(E9>0, N9+E9,"")
A10: Jerod | B10: Senton | C10: =IF(F10="Alive",D10+G10," ") -> 15 | D10: 10 | F10: Alive | G10: 5 | H10: =IF(F10="Dead",G10+D10," ") | I10: 60 | J10: 55 | K10: 75 | L10: 90 | M10: =IF(SUM(I10:L10)>0,AVERAGE(I10:L10)," ") -> 70 | N10: =O10-G10-D10 -> 1174 | O10: 1189 | P10: =IF(E10>0, N10+E10,"")
A11: Garin | B11: Hearston | C11: =IF(F11="Alive",D11+G11," ") | D11: 61 | E11: 64 | F11: Dead | G11: 5 | H11: =IF(F11="Dead",G11+D11," ") -> 66 | I11: 60 | J11: 10 | K11: 90 | L11: 80 | M11: =IF(SUM(I11:L11)>0,AVERAGE(I11:L11)," ") -> 60 | N11: =O11-G11-D11 -> 1123 | O11: 1189 | P11: =IF(E11>0, N11+E11,"") -> 1187
A12: Harrison | B12: Hearston | C12: =IF(F12="Alive",D12+G12," ") -> 40 | D12: 35 | F12: Alive | G12: 5 | H12: =IF(F12="Dead",G12+D12," ") | I12: 80 | J12: 60 | K12: 50 | L12: 90 | M12: =IF(SUM(I12:L12)>0,AVERAGE(I12:L12)," ") -> 70 | N12: =O12-G12-D12 -> 1149 | O12: 1189 | P12: =IF(E12>0, N12+E12,"")
A13: John | B13: Hearston | C13: =IF(F13="Alive",D13+G13," ") -> 35 | D13: 30 | F13: Alive | G13: 5 | H13: =IF(F13="Dead",G13+D13," ") | I13: 55 | J13: 70 | K13: 100 | L13: 50 | M13: =IF(SUM(I13:L13)>0,AVERAGE(I13:L13)," ") -> 68.75 | N13: =O13-G13-D13 -> 1154 | O13: 1189 | P13: =IF(E13>0, N13+E13,"")
A14: Anne | B14: Hearston | C14: =IF(F14="Alive",D14+G14," ") -> 22 | D14: 17 | F14: Alive | G14: 5 | H14: =IF(F14="Dead",G14+D14," ") | I14: 50 | J14: 30 | K14: 90 | L14: 75 | M14: =IF(SUM(I14:L14)>0,AVERAGE(I14:L14)," ") -> 61.25 | N14: =O14-G14-D14 -> 1167 | O14: 1189 | P14: =IF(E14>0, N14+E14,"")
A15: Robert | B15: Hearston | C15: =IF(F15="Alive",D15+G15," ") -> 20 | D15: 15 | F15: Alive | G15: 5 | H15: =IF(F15="Dead",G15+D15," ") | I15: 65 | J15: 80 | K15: 90 | L15: 75 | M15: =IF(SUM(I15:L15)>0,AVERAGE(I15:L15)," ") -> 77.5 | N15: =O15-G15-D15 -> 1169 | O15: 1189 | P15: =IF(E15>0, N15+E15,"")
A16: Arthur | B16: Hearston | C16: =IF(F16="Alive",D16+G16," ") -> 18 | D16: 13 | F16: Alive | G16: 5 | H16: =IF(F16="Dead",G16+D16," ") | I16: 80 | J16: 75 | K16: 55 | L16: 65 | M16: =IF(SUM(I16:L16)>0,AVERAGE(I16:L16)," ") -> 68.75 | N16: =O16-G16-D16 -> 1171 | O16: 1189 | P16: =IF(E16>0, N16+E16,"")
A17: Frederick | B17: Reynar | C17: =IF(F17="Alive",D17+G17," ") -> 53 | D17: 48 | F17: Alive | G17: 5 | H17: =IF(F17="Dead",G17+D17," ") | M17: =IF(SUM(I17:L17)>0,AVERAGE(I17:L17)," ") | N17: =O17-G17-D17 -> 1136 | O17: 1189 | P17: =IF(E17>0, N17+E17,"")
A18: Elena | B18: Reynar | C18: =IF(F18="Alive",D18+G18," ") -> 19 | D18: 14 | F18: Alive | G18: 5 | H18: =IF(F18="Dead",G18+D18," ") | I18: 80 | J18: 20 | K18: 75 | L18: 65 | M18: =IF(SUM(I18:L18)>0,AVERAGE(I18:L18)," ") -> 60 | N18: =O18-G18-D18 -> 1170 | O18: 1189 | P18: =IF(E18>0, N18+E18,"")
A19: Ignisell | B19: Ardere | C19: =IF(F19="Alive",D19+G19," ") -> 34 | D19: 29 | F19: Alive | G19: 5 | H19: =IF(F19="Dead",G19+D19," ") | I19: 105 | J19: 20 | K19: 90 | L19: 55 | M19: =IF(SUM(I19:L19)>0,AVERAGE(I19:L19)," ") -> 67.5 | N19: =O19-G19-D19 -> 1155 | O19: 1189 | P19: =IF(E19>0, N19+E19,"")
A20: Reed | B20: Lowborn | C20: =IF(F20="Alive",D20+G20," ") -> 34 | D20: 29 | F20: Alive | G20: 5 | H20: =IF(F20="Dead",G20+D20," ") | I20: 120 | J20: 15 | K20: 70 | L20: 100 | M20: =IF(SUM(I20:L20)>0,AVERAGE(I20:L20)," ") -> 76.25 | N20: =O20-G20-D20 -> 1155 | O20: 1189 | P20: =IF(E20>0, N20+E20,"")
A21: Wilson | B21: Carthen | C21: =IF(F21="Alive",D21+G21," ") -> 25 | D21: 20 | F21: Alive | G21: 5 | H21: =IF(F21="Dead",G21+D21," ") | M21: =IF(SUM(I21:L21)>0,AVERAGE(I21:L21)," ") | N21: =O21-G21-D21 -> 1164 | O21: 1189 | P21: =IF(E21>0, N21+E21,"")
A22: Atia | B22: Carthen | C22: =IF(F22="Alive",D22+G22," ") | D22: 26 | E22: 26 | F22: Dead | G22: 5 | H22: =IF(F22="Dead",G22+D22," ") -> 31 | I22: 65 | J22: 10 | K22: 110 | L22: 50 | M22: =IF(SUM(I22:L22)>0,AVERAGE(I22:L22)," ") -> 58.75 | N22: =O22-G22-D22 -> 1158 | O22: 1189 | P22: =IF(E22>0, N22+E22,"") -> 1184
A23: Cimon | B23: Carthen | C23: =IF(F23="Alive",D23+G23," ") | D23: 35 | G23: 5 | H23: =IF(F23="Dead",G23+D23," ") | I23: 100 | J23: 45 | K23: 65 | L23: 50 | M23: =IF(SUM(I23:L23)>0,AVERAGE(I23:L23)," ") -> 65 | N23: =O23-G23-D23 -> 1149 | O23: 1189 | P23: =IF(E23>0, N23+E23,"")
A24: Chelsey | B24: Carthen | C24: =IF(F24="Alive",D24+G24," ") | G24: 5 | H24: =IF(F24="Dead",G24+D24," ") | M24: =IF(SUM(I24:L24)>0,AVERAGE(I24:L24)," ") | N24: =O24-G24-D24 -> 1184 | O24: 1189 | P24: =IF(E24>0, N24+E24,"")
G25: 5 | H25: =IF(F25="Dead",G25+D25," ") | N25: =O25-G25-D25 -> 1184 | O25: 1189 | P25: =IF(E25>0, N25+E25,"")
G26: 5 | H26: =IF(F26="Dead",G26+D26," ") | N26: =O26-G26-D26 -> 1184 | O26: 1189 | P26: =IF(E26>0, N26+E26,"")
G27: 5 | H27: =IF(F27="Dead",G27+D27," ") | N27: =O27-G27-D27 -> 1184 | O27: 1189 | P27: =IF(E27>0, N27+E27,"")
G28: 5 | N28: =O28-G28-D28 -> 1184 | O28: 1189 | P28: =IF(E28>0, N28+E28,"")
G29: 5 | N29: =O29-G29-D29 -> 1184 | O29: 1189 | P29: =IF(E29>0, N29+E29,"")
G30: 5 | N30: =O30-G30-D30 -> 1184 | O30: 1189 | P30: =IF(E30>0, N30+E30,"")
G31: 5 | N31: =O31-G31-D31 -> 1184 | O31: 1189 | P31: =IF(E31>0, N31+E31,"")
G32: 5 | N32: =O32-G32-D32 -> 1184 | O32: 1189 | P32: =IF(E32>0, N32+E32,"")
G33: 5 | N33: =O33-G33-D33 -> 1184 | O33: 1189 | P33: =IF(E33>0, N33+E33,"")
G34: 5 | N34: =O34-G34-D34 -> 1184 | O34: 1189 | P34: =IF(E34>0, N34+E34,"")
G35: 5 | N35: =O35-G35-D35 -> 1184 | O35: 1189 | P35: =IF(E35>0, N35+E35,"")
G36: 5 | N36: =O36-G36-D36 -> -5 | P36: =IF(E36>0, N36+E36,"")
G37: 5 | N37: =O37-G37-D37 -> -5 | P37: =IF(E37>0, N37+E37,"")
A50: Average | I50: =AVERAGE(I2:I49) -> 68.529412 | J50: =AVERAGE(J2:J49) -> 52.941176 | K50: =AVERAGE(K2:K49) -> 76.764706 | L50: =AVERAGE(L2:L49) -> 63.823529 | M50: =AVERAGE(M2:M49) -> 65.514706
A51: Median | I51: =MEDIAN(I2:I49) -> 65 | J51: =MEDIAN(J2:J49) -> 45 | K51: =MEDIAN(K2:K49) -> 75 | L51: =MEDIAN(L2:L49) -> 65 | M51: =MEDIAN(M2:M49) -> 66.25

Sheet Characters
A1: Name | B1: Wilson Carthen | C1: Reed Carthen | D1: Cimon Carthen | E1: Edmund Konthern II | F1: Emilan Konthern | G1: Ellan Konthern | H1: Harrison Hearston | I1: John Hearston | J1: Robert Hearston | K1: Ignisell Ardere | L1: Aura Letum | M1: Edrick of Ravenmark | N1: Jason Senton | O1: Gabren Princeps | P1: John Senton | Q1: Gordon Merek | R1: Philson Merek | S1: Henry Merek | T1: Atia Carthen | U1: Colin 'Pearl' | V1: Sir Marcus Ferrum | W1: Garin Hearston | X1: Armin Princeps | Z1: Avg | AA1: Median
A2: Discord Username | B2: vengeance014 | C2: ICBM | D2: penuppy | E2: banaenae | F2: jasuiman | G2: veronyx | H2: lucid219 | I2: en56yaw4536 | J2: thebookman10 | K2: okwithme | L2: rub.rubens11 | M2: RAW | N2: Smach | O2: TheClickBateM8 | P2: admiwart | Q2: TheGuy | R2: bigbois744 | S2: .titanlord | T2: rub.rubens11 | U2: Squidkid13 | V2: .titanlord | W2: amibcool | X2: surewarboii
A3: House | B3: Carthen | C3: Lowborn | D3: Carthen | E3: Konthern | F3: Konthern | G3: Konthern | H3: Hearston | I3: Hearston | J3: Hearston | K3: Ardere | L3: Letum | M3: Lowborn | N3: Senton | O3: Merek | P3: Senton | Q3: Merek | R3: Merek | S3: Merek | T3: Carthen | U3: Lowborn | V3: Ferrum | W3: Hearston | X3: Princeps
A4: Age | B4: 23 | C4: 33 | D4: 39 | E4: 44 | F4: 20 | G4: 22 | H4: 38 | I4: 35 | J4: 18 | K4: 33 | L4: 21 | M4: 30 | N4: 19 | O4: 20 | P4: 25 | Q4: 21 | R4: 43 | S4: 23 | T4: 26 | U4: 31 | V4: 22 | W4: 64 | X4: 20 | Z4: =AVERAGE(B4:T4) -> 28.052632 | AA4: =MEDIAN(B4:T4) -> 25
A5: Gender | B5: Male | C5: Male | D5: Male | E5: Male | F5: Male | G5: Female | H5: Male | I5: Male | J5: Male | K5: Male | L5: Female (?) | N5: Male | O5: Male | P5: Male | Q5: Male | R5: Male | S5: Male | T5: Female | U5: Male | V5: Male (?) | W5: Male | X5: Male
A6: Stress Level | B6: 0 | C6: 0 | D6: 0 | E6: 0 | F6: 0 | H6: 1 | I6: 0.5 | L6: 100000 | O6: 0 | Q6: 0 | R6: 0 | S6: 0 | T6: 0 | V6: 1.01 | W6: 0 | X6: 0
A7: Intrigue Skill | B7: 70 | C7: 120 | D7: 100 | E7: 20 | F7: 55 | G7: 100 | H7: 80 | I7: 55 | J7: 65 | K7: 105 | L7: 100 | M7: 50 | N7: 50 | O7: 60 | P7: 65 | Q7: 50 | R7: 60 | S7: 50 | T7: 65 | U7: 80 | V7: 70 | W7: 60 | X7: 35 | Z7: =AVERAGE(B7:T7) -> 69.473684 | AA7: =MEDIAN(B7:T7) -> 65
A8: Combat Skill | B8: 85 | C8: 15 | D8: 45 | E8: 75 | F8: 90 | G8: 20 | H8: 60 | I8: 70 | J8: 80 | K8: 20 | L8: 15 | M8: 50 | N8: 90 | O8: 40 | P8: 45 | Q8: 90 | R8: 40 | S8: 80 | T8: 10 | U8: 70 | V8: 110 | W8: 10 | X8: 125 | Z8: =AVERAGE(B8:T8) -> 53.684211 | AA8: =MEDIAN(B8:T8) -> 50
A9: Diplomacy Skill | B9: 50 | C9: 70 | D9: 65 | E9: 85 | F9: 35 | G9: 90 | H9: 50 | I9: 100 | J9: 90 | K9: 90 | L9: 75 | M9: 50 | N9: 65 | O9: 60 | P9: 90 | Q9: 30 | R9: 100 | S9: 40 | T9: 110 | U9: 85 | V9: 65 | W9: 90 | X9: 50 | Z9: =AVERAGE(B9:T9) -> 70.789474 | AA9: =MEDIAN(B9:T9) -> 70
A10: Stewardship Skill | B10: 20 | C10: 100 | D10: 50 | E10: 70 | F10: 60 | G10: 45 | H10: 90 | I10: 50 | J10: 75 | K10: 55 | L10: 65 | M10: 50 | N10: 45 | O10: 35 | P10: 80 | Q10: 80 | R10: 50 | S10: 70 | T10: 50 | U10: 40 | V10: 35 | W10: 80 | X10: 40 | Z10: =AVERAGE(B10:T10) -> 60 | AA10: =MEDIAN(B10:T10) -> 55
A11: Avg Skill | B11: =B12/4 -> 56.25 | C11: =C12/4 -> 76.25 | D11: =D12/4 -> 65 | E11: =E12/4 -> 62.5 | F11: =F12/4 -> 60 | G11: =G12/4 -> 63.75 | H11: =H12/4 -> 70 | I11: =I12/4 -> 68.75 | ... X11: =X12/4 -> 62.5 | Z11: =AVERAGE(B11:T11) -> 63.486842 | AA11: =MEDIAN(B11:T11) -> 62.5
A12: Total Skill | B12: =SUM(B7:B10) -> 225 | C12: =SUM(C7:C10) -> 305 | D12: =SUM(D7:D10) -> 260 | E12: =SUM(E7:E10) -> 250 | F12: =SUM(F7:F10) -> 240 | G12: =SUM(G7:G10) -> 255 | H12: =SUM(H7:H10) -> 280 | I12: =SUM(I7:I10) -> 275 | ... X12: =SUM(X7:X10) -> 250 | Z12: =AVERAGE(B12:T12) -> 253.94737 | AA12: =MEDIAN(B12:T12) -> 250
A14: Future Age | B14: =B4+1 -> 24 | C14: =C4+1 -> 34 | D14: =D4+1 -> 40 | E14: =E4+1 -> 45 | F14: =F4+1 -> 21 | G14: =G4+1 -> 23 | H14: =H4+1 -> 39 | I14: =I4+1 -> 36 | ... N14: =N4+1 -> 20 | U14: =U4+1 -> 32 | V14: =V4+1 -> 23 | W14: =W4+1 -> 65 | X14: =X4+1 -> 21

Sheet NPCs
A1: Name | B1: Sir Finley Lowborn | C1: Sir Jory Senton | D1: Maxwell Smithson | E1: Sir Seiron "The Old" | F1: The Patriarch | G1: Frederick Reynar | H1: Elena Reynar | I1: Anne Hearston | J1: Val Ecton | L1: Avg | M1: Median
A2: House | C2: Senton | D2: Smithson | F2: Unknown | G2: Reynar | H2: Reynar | I2: Hearston | J2: Ecton
A3: Age | B3: 24 | C3: 21 | D3: 38 | E3: 53 | F3: 47 | G3: 52 | H3: 18 | I3: 20 | J3: 19 | L3: =AVERAGE(B3:J3) -> 32.444444 | M3: =MEDIAN(B3:J3) -> 24
A4: Gender | B4: Male | C4: Male | D4: Male | E4: Male | F4: Male | G4: Male | H4: Female | I4: Female
A5: Intrigue Skill | B5: 65 | C5: 35 | D5: 0 | E5: 40 | F5: ??? | G5: 50 | H5: 80 | I5: 50 | J5: 55 | L5: =AVERAGE(B5:J5) -> 46.875 | M5: =MEDIAN(B5:J5) -> 50
A6: Combat Skill | B6: 85 | C6: 110 | D6: 105 | E6: 70 | F6: ??? | G6: 80 | H6: 20 | I6: 30 | J6: 90 | L6: =AVERAGE(B6:J6) -> 73.75 | M6: =MEDIAN(B6:J6) -> 82.5
A7: Diplomacy Skill | B7: 30 | C7: 80 | D7: 35 | E7: 45 | F7: ??? | G7: 75 | H7: 75 | I7: 90 | J7: 75 | L7: =AVERAGE(B7:J7) -> 63.125 | M7: =MEDIAN(B7:J7) -> 75
A8: Stewardship Skill | B8: 40 | C8: 40 | D8: 40 | E8: 60 | F8: ??? | G8: 45 | H8: 65 | I8: 75 | J8: 60 | L8: =AVERAGE(B8:J8) -> 53.125 | M8: =MEDIAN(B8:J8) -> 52.5
B9: =SUM(B5:B8) -> 220 | C9: =SUM(C5:C8) -> 265 | D9: =SUM(D5:D8) -> 180 | E9: =SUM(E5:E8) -> 215 | F9: =SUM(F5:F8) -> 0 | G9: =SUM(G5:G8) -> 250 | H9: =SUM(H5:H8) -> 240 | I9: =SUM(I5:I8) -> 245 | J9: =SUM(J5:J8) -> 280 | L9: =AVERAGE(B9:J9) -> 210.55556 | M9: =MEDIAN(B9:J9) -> 240
B10: =B3+1 -> 25 | C10: =C3+1 -> 22 | D10: =D3+1 -> 39 | E10: =E3+1 -> 54 | F10: =F3+1 -> 48 | G10: =G3+1 -> 53 | H10: =H3+1 -> 19 | I10: =I3+1 -> 21 | J10: =J3+1 -> 20

Sheet Secret Sheet
A1: Crownlands | B1: 0 | C1: 0 | D1: =C1-F1 -> 0 | E1: =(Provinces!C2*0.005)-F1 -> 30993.535 | F1: =SUM(G1:I1) -> 0 | I1: =(C1*0.02)*J1 -> 0 | K1: =IF(AND('The Crown'!B2<0,C1>0),1,0) -> 0
A2: Dreghold | B2: 0.25 | C2: 55000 | D2: =C2-F2 -> 45561 | E2: =(Provinces!C3*0.005)-F2 -> 55800.15 | F2: =SUM(G2:I2) -> 9439 | G2: 1034 | H2: 4005 | I2: =(C2*0.02)*J2 -> 4400 | J2: 4 | K2: =IF(AND(Provinces!B3<0,C2>0),1,0) -> 1
A3: Madinglia | B3: 0 | C3: 18000 | D3: =C3-F3 -> 18000 | E3: =(Provinces!C4*0.005)-F3 -> 18696.055 | F3: =SUM(G3:I3) -> 0 | I3: =(C3*0.02)*J3 -> 0 | K3: =IF(AND(Provinces!B4<0,C3>0),1,0) -> 0
A4: Pearlpass | B4: 0.25 | C4: 0 | D4: =C4-F4 -> 0 | E4: =(Provinces!C5*0.005)-F4 -> 15912.62 | F4: =SUM(G4:I4) -> 0 | I4: =(C4*0.02)*J4 -> 0 | K4: =IF(AND(Provinces!B5<0,C4>0),1,0) -> 0
A5: Ralim | B5: 0.25 | C5: 0 | D5: =C5-F5 -> 0 | E5: =(Provinces!C6*0.005)-F5 -> 38470.655 | F5: =SUM(G5:I5) -> 0 | I5: =(C5*0.02)*J5 -> 0 | K5: =IF(AND(Provinces!B6<0,C5>0),1,0) -> 0
A6: Sirong | B6: 0.25 | C6: 26500 | D6: =C6-F6 -> 16275 | E6: =(Provinces!C7*0.005)-F6 -> 69979.68 | F6: =SUM(G6:I6) -> 10225 | G6: 4000 | H6: 4105 | I6: =(C6*0.02)*J6 -> 2120 | J6: 4 | K6: =IF(AND(Provinces!B7<0,C6>0),1,0) -> 1
A7: Swanhall | B7: 0.25 | C7: 3000 | D7: =C7-F7 -> 1111 | E7: =(Provinces!C8*0.005)-F7 -> 83146.18 | F7: =SUM(G7:I7) -> 1889 | G7: 1035 | H7: 854 | I7: =(C7*0.02)*J7 -> 0 | K7: =IF(AND(Provinces!B8<0,C7>0),1,0) -> 0
B8: Province Tax Rates | C8: Raised Levies | D8: True Raised | E8: True Possible Levies | F8: Casualties | G8: Injured | H8: Dead | I8: Deserted | J8: Ticks Without Pay | K8: Without Pay T/F | L8: Current Casualties | M8: Tentative Casualties | N8: Future Casualties

Sheet Lesser House Dominions
B1: Gold Kastar Coins | C1: Total Population | D1: Urban Population | E1: Rural Population | F1: Gold Net Income | G1: Retinues | H1: Raised Levys | I1: Possible Levys | J1: Projected Gold | K1: Urban Population % | L1: Rural Population %
A2: Sentons | B2: -1889.438 | C2: =D2+E2 -> 468927 | D2: =Cities!E102 -> 19353 | E2: 449574 | F2: =Economics!B9-Economics!C9 -> 749.27992 | G2: ='Retinue Breakdown'!R10 -> 50 | I2: =C2*0.005 -> 2344.635 | J2: =B2+F2 -> -1140.1581 | K2: =D2/C2 -> 0.041270816 | L2: =E2/C2 -> 0.95872918 | M2: =B2+F2 -> -1140.1581
B3: 0 | J3: =B3+F3 -> 0 | K3: =D3/C3 -> #DIV/0! | L3: =E3/C3 -> #DIV/0! | M3: =B3+F3 -> 0
B4: 0 | J4: =B4+F4 -> 0 | K4: =D4/C4 -> #DIV/0! | L4: =E4/C4 -> #DIV/0! | M4: =B4+F4 -> 0
B5: 0 | J5: =B5+F5 -> 0 | K5: =D5/C5 -> #DIV/0! | L5: =E5/C5 -> #DIV/0! | M5: =B5+F5 -> 0
B6: 0 | J6: =B6+F6 -> 0 | K6: =D6/C6 -> #DIV/0! | L6: =E6/C6 -> #DIV/0! | M6: =B6+F6 -> 0
B7: 0 | J7: =B7+F7 -> 0 | K7: =D7/C7 -> #DIV/0! | L7: =E7/C7 -> #DIV/0! | M7: =B7+F7 -> 0
B8: 0 | J8: =B8+F8 -> 0 | K8: =D8/C8 -> #DIV/0! | L8: =E8/C8 -> #DIV/0! | M8: =B8+F8 -> 0
A9: Average | B9: =AVERAGE(B2:B8) -> -269.91972 | C9: =AVERAGE(C2:C8) -> 468927 | D9: =AVERAGE(D2:D8) -> 19353 | E9: =AVERAGE(E2:E8) -> 449574 | F9: =AVERAGE(F2:F8) -> 749.27992 | G9: =AVERAGE(G2:G8) -> 50 | I9: =AVERAGE('Secret Sheet'!E1:E7) -> 44714.125 | J9: =AVERAGE(J2:J8) -> -162.87973 | K9: =AVERAGE(K2:K8) -> #DIV/0! | L9: =AVERAGE(L2:L8) -> #DIV/0! | M9: =B9+F9 -> 479.3602
A10: Total | B10: =SUM(B2:B8) -> -1889.438 | C10: =SUM(C2:C8) -> 468927 | D10: =SUM(D2:D8) -> 19353 | E10: =SUM(E2:E8) -> 449574 | F10: =SUM(F2:F8) -> 749.27992 | G10: =SUM(G2:G8) -> 50 | I10: =SUM('Secret Sheet'!E1:E7) -> 312998.88 | J10: =SUM(J2:J8) -> -1140.1581 | M10: =B10+F10 -> -1140.1581

Sheet Economics
B1: Gold Income | C1: Gold Spending | D1: Final Total Tax Income | E1: Raw Total Tax Income | F1: Urban Tax Income | G1: Rural Tax Income | H1: Diplomatic Income | I1: Total Military Spending | J1: Retinue Spending | K1: Levy Spending | L1: Diplomatic Spending
A2: Crownlands | D2: =E2*(1-'Secret Sheet'!B1) -> 7416.5166 | E2: =SUM(F2:G2) -> 7416.5166 | F2: =SUM(Cities!P3:P13) -> 3824.355 | G2: ='Price Sheet (Ignore)'!$G$2*((Provinces!E2/5)*'Price Sheet (Ignore)'!$I$2) -> 3592.1616 | H2: 0 | I2: =J2+K2 -> 2917.9483 | J2: ='Retinue Breakdown'!R12 -> 2670 | K2: =Provinces!H2*2+'Secret Sheet'!E1*0.008 -> 247.94828 | L2: 500
A3: Dreghold | B3: =D3+H3 -> 8787.5312 | C3: =I3+L3 -> 93068.401 | D3: =E3*(1-'Secret Sheet'!B2) -> 8787.5312 | E3: =SUM(F3:G3) -> 11716.708 | F3: =SUM(Cities!P4:P14) -> 4014.0217 | G3: ='Price Sheet (Ignore)'!$G$2*((Provinces!E3/5)*'Price Sheet (Ignore)'!$I$2) -> 7702.6866 | H3: 0 | I3: =J3+K3 -> 93068.401 | J3: ='Retinue Breakdown'!R13 -> 1500 | K3: =Provinces!H3*2+'Secret Sheet'!E2*0.008 -> 91568.401 | L3: 0
A4: Madinglia | B4: =D4+H4 -> 7240.3267 | C4: =I4+L4 -> 38649.568 | D4: =E4*(1-'Secret Sheet'!B3) -> 6040.3267 | E4: =SUM(F4:G4) -> 6040.3267 | F4: =SUM(Cities!P5:P15) -> 3840.3217 | G4: ='Price Sheet (Ignore)'!$G$2*((Provinces!E4/5)*'Price Sheet (Ignore)'!$I$2) -> 2200.005 | H4: 1200 | I4: =J4+K4 -> 38649.568 | J4: ='Retinue Breakdown'!R14 -> 2500 | K4: =Provinces!H4*2+'Secret Sheet'!E3*0.008 -> 36149.568 | L4: 0
A5: Pearlpass | B5: =D5+H5 -> 4684.7541 | C5: =I5+L5 -> 1627.301 | D5: =E5*(1-'Secret Sheet'!B4) -> 4684.7541 | E5: =SUM(F5:G5) -> 6246.3388 | F5: =SUM(Cities!P6:P16) -> 4350.37 | G5: ='Price Sheet (Ignore)'!$G$2*((Provinces!E5/5)*'Price Sheet (Ignore)'!$I$2) -> 1895.9688 | H5: 0 | I5: =J5+K5 -> 1627.301 | J5: ='Retinue Breakdown'!R15 -> 1500 | K5: =Provinces!H5*2+'Secret Sheet'!E4*0.008 -> 127.30096 | L5: 0
A6: Ralim | B6: =D6+H6 -> 6617.7505 | C6: =I6+L6 -> 1807.7652 | D6: =E6*(1-'Secret Sheet'!B5) -> 6617.7505 | E6: =SUM(F6:G6) -> 8823.6673 | F6: =SUM(Cities!P7:P17) -> 4286.7433 | G6: ='Price Sheet (Ignore)'!$G$2*((Provinces!E6/5)*'Price Sheet (Ignore)'!$I$2) -> 4536.924 | H6: 0 | I6: =J6+K6 -> 1807.7652 | J6: ='Retinue Breakdown'!R16 -> 1500 | K6: =Provinces!H6*2+'Secret Sheet'!E5*0.008 -> 307.76524 | L6: 0
A7: Sirong | B7: =D7+H7 -> 9860.1282 | C7: =I7+L7 -> 34709.837 | D7: =E7*(1-'Secret Sheet'!B6) -> 9860.1282 | E7: =SUM(F7:G7) -> 13146.838 | F7: =SUM(Cities!P8:P18) -> 3798.5767 | G7: ='Price Sheet (Ignore)'!$G$2*((Provinces!E7/5)*'Price Sheet (Ignore)'!$I$2) -> 9348.261 | H7: 0 | I7: =J7+K7 -> 34709.837 | J7: ='Retinue Breakdown'!R17 -> 1600 | K7: =Provinces!H7*2+'Secret Sheet'!E6*0.008 -> 33109.837 | L7: 0
A8: Swanhall | B8: =D8+H8 -> 10699.256 | C8: =I8+L8 -> 4387.1694 | D8: =E8*(1-'Secret Sheet'!B7) -> 10149.256 | E8: =SUM(F8:G8) -> 13532.342 | F8: =SUM(Cities!P9:P19) -> 3675.8767 | G8: ='Price Sheet (Ignore)'!$G$2*((Provinces!E8/5)*'Price Sheet (Ignore)'!$I$2) -> 9856.4652 | H8: 550 | I8: =J8+K8 -> 4387.1694 | J8: ='Retinue Breakdown'!R18 -> 1500 | K8: =Provinces!H8*2+'Secret Sheet'!E7*0.008 -> 2887.1694 | L8: 0
A9: Sentons | B9: =D9+H9 -> 2268.037 | C9: =I9+L9 -> 1518.7571 | D9: =E9 -> 1768.037 | E9: =SUM(F9:G9) -> 1768.037 | F9: =Cities!P102 -> 419.315 | G9: ='Price Sheet (Ignore)'!$G$2*(('Lesser House Dominions'!E2)*'Price Sheet (Ignore)'!$I$2) -> 1348.722 | H9: 500 | I9: =J9+K9 -> 1518.7571 | J9: ='Retinue Breakdown'!R19 -> 1500 | K9: ='Lesser House Dominions'!H2*2+'Lesser House Dominions'!I2*0.008 -> 18.75708 | L9: 0
A10: The Crown | B10: =D10+H10+D2 -> 20782.99 | C10: =I2+L2 -> 3417.9483 | D10: =(E11-D11) -> 13366.473 | H10: =H2 -> 0 | I10: =I2 -> 2917.9483 | J10: =J2 -> 2670 | K10: =K2 -> 247.94828 | L10: 0
